<?xml version="1.0" ?>
<robot name="moodz" xmlns:xacro="http://www.ros.org/wiki/xacro">

<xacro:include filename="$(find moodz_description)/urdf/materials.xacro" />
<xacro:include filename="$(find moodz_description)/urdf/moodz.trans" />
<xacro:include filename="$(find moodz_description)/urdf/moodz.gazebo" />
<link name="base_link">
  <inertial>
    <origin rpy="0 0 0" xyz="0.003563875604623609 3.688815650635801e-17 0.14918957693465243"/>
    <mass value="33.45253675533549"/>
    <inertia ixx="0.504373" ixy="0.0" ixz="-0.01326" iyy="0.793057" iyz="0.0" izz="1.138721"/>
  </inertial>
  <visual>
    <origin rpy="0 0 0" xyz="0 0 0"/>
    <geometry>
      <mesh filename="package://moodz_description/meshes/base_link.stl" scale="0.001 0.001 0.001"/>
    </geometry>
    <material name="silver"/>
  </visual>
  <collision>
    <origin rpy="0 0 0" xyz="0 0 0"/>
    <geometry>
      <mesh filename="package://moodz_description/meshes/base_link.stl" scale="0.001 0.001 0.001"/>
    </geometry>
  </collision>
</link>

<link name="right_wheel_1">
  <inertial>
    <origin rpy="0 0 0" xyz="0.0 -0.03750000000000003 2.7755575615628914e-17"/>
    <mass value="4.93033697072748"/>
    <inertia ixx="0.030044" ixy="0.0" ixz="-0.0" iyy="0.055466" iyz="-0.0" izz="0.030044"/>
  </inertial>
  <visual>
    <origin rpy="0 0 0" xyz="-0.0 0.2 -0.15"/>
    <geometry>
      <mesh filename="package://moodz_description/meshes/right_wheel_1.stl" scale="0.001 0.001 0.001"/>
    </geometry>
    <material name="silver"/>
  </visual>
  <collision>
    <origin rpy="0 0 0" xyz="-0.0 0.2 -0.15"/>
    <geometry>
      <mesh filename="package://moodz_description/meshes/right_wheel_1.stl" scale="0.001 0.001 0.001"/>
    </geometry>
  </collision>
</link>

<link name="left_wheel_1">
  <inertial>
    <origin rpy="0 0 0" xyz="0.0 0.03749999999999998 2.7755575615628914e-17"/>
    <mass value="4.93033697072748"/>
    <inertia ixx="0.030044" ixy="0.0" ixz="-0.0" iyy="0.055466" iyz="0.0" izz="0.030044"/>
  </inertial>
  <visual>
    <origin rpy="0 0 0" xyz="-0.0 -0.2 -0.15"/>
    <geometry>
      <mesh filename="package://moodz_description/meshes/left_wheel_1.stl" scale="0.001 0.001 0.001"/>
    </geometry>
    <material name="silver"/>
  </visual>
  <collision>
    <origin rpy="0 0 0" xyz="-0.0 -0.2 -0.15"/>
    <geometry>
      <mesh filename="package://moodz_description/meshes/left_wheel_1.stl" scale="0.001 0.001 0.001"/>
    </geometry>
  </collision>
</link>

<link name="lidar_1">
  <inertial>
    <origin rpy="0 0 0" xyz="-2.7755575615628914e-17 5.790023100122029e-18 0.024999999999999967"/>
    <mass value="0.5615596868291755"/>
    <inertia ixx="0.000468" ixy="0.0" ixz="-0.0" iyy="0.000468" iyz="0.0" izz="0.000702"/>
  </inertial>
  <visual>
    <origin rpy="0 0 0" xyz="-0.175 -0.0 -0.3"/>
    <geometry>
      <mesh filename="package://moodz_description/meshes/lidar_1.stl" scale="0.001 0.001 0.001"/>
    </geometry>
    <material name="silver"/>
  </visual>
  <collision>
    <origin rpy="0 0 0" xyz="-0.175 -0.0 -0.3"/>
    <geometry>
      <mesh filename="package://moodz_description/meshes/lidar_1.stl" scale="0.001 0.001 0.001"/>
    </geometry>
  </collision>
</link>

<link name="camera_1">
  <inertial>
    <origin rpy="0 0 0" xyz="0.012500000000000011 0.0 0.0"/>
    <mass value="0.3575"/>
    <inertia ixx="0.001266" ixy="0.0" ixz="0.0" iyy="9.3e-05" iyz="0.0" izz="0.00121"/>
  </inertial>
  <visual>
    <origin rpy="0 0 0" xyz="-0.25 -0.0 -0.15"/>
    <geometry>
      <mesh filename="package://moodz_description/meshes/camera_1.stl" scale="0.001 0.001 0.001"/>
    </geometry>
    <material name="silver"/>
  </visual>
  <collision>
    <origin rpy="0 0 0" xyz="-0.25 -0.0 -0.15"/>
    <geometry>
      <mesh filename="package://moodz_description/meshes/camera_1.stl" scale="0.001 0.001 0.001"/>
    </geometry>
  </collision>
</link>
<link name="camera_link_optical">
</link>
<joint name="camera_optical_joint" type="fixed">
<origin xyz="0 0 0" rpy="-1.58 0 -1.58"/>
<parent link="camera_1"/>
<child link="camera_link_optical"/>
</joint>

<joint name="Rev1" type="continuous">

  <origin rpy="0 0 0" xyz="0.0 -0.2 0.15"/>
  <parent link="base_link"/>
  <child link="right_wheel_1"/>
  <axis xyz="0.0 1.0 0.0"/>
</joint>

<joint name="Rev2" type="continuous">
  <origin rpy="0 0 0" xyz="0.0 0.2 0.15"/>
  <parent link="base_link"/>
  <child link="left_wheel_1"/>
  <axis xyz="0.0 1.0 0.0"/>
</joint>

<joint name="Rev3" type="fixed">
  <origin rpy="0 0 0" xyz="0.175 0.0 0.3"/>
  <parent link="base_link"/>
  <child link="lidar_1"/>
  <axis xyz="0.0 1.0 0.0"/>
</joint>

<joint name="Rigid4" type="fixed">
  <origin rpy="0 0 0" xyz="0.25 0.0 0.15"/>
  <parent link="base_link"/>
  <child link="camera_1"/>
  <axis xyz="0 1 0"/>
</joint>

</robot>
